import { ApiError } from '../exceptions/api-error.js';




export const historyWeather =  async(req, res, next) =>  {
    try{
        // const users = await userService.getAllUsers();
        // return res.json(users)

    }catch(err){
        next(err)
    }
}
export const currentWeather =  async(req, res, next) =>  {
    try{
        // const users = await userService.getAllUsers();
        // return res.json(users)

    }catch(err){
        next(err)
    }
}
export const forecastWeather =  async(req, res, next) =>  {
    try{
        // const users = await userService.getAllUsers();
        // return res.json(users)

    }catch(err){
        next(err)
    }
}
export const climatWeather =  async(req, res, next) =>  {
    try{
        // const users = await userService.getAllUsers();
        // return res.json(users)

    }catch(err){
        next(err)
    }
}











